Workbook
Name CraftableID: '01_Craftable'!$B:$B
Name CraftableName: '01_Craftable'!$C:$C
Name LocationID: '02_Location'!$A:$A
Name LocationName: '02_Location'!$B:$B

Sheet PowerDashboard
A1: Advanced Component Search | AQ1: {=_xlfn._xlws.SORT(_xlfn.UNIQUE(tblComponent[ComponentRarity]))} -> Blue | AR1: {=_xlfn._xlws.SORT(_xlfn.UNIQUE(tblLocation[LocationName]))} -> ARC | AS1: {=_xlfn._xlws.SORT(_xlfn.UNIQUE(tblCraftable[CraftableName]))} -> Adrenaline Shot | AT1: {=_xlfn._xlws.SORT(_xlfn.UNIQUE(tblComponent[ComponentName]))} -> Advanced ARC Powercell
AQ2: Gray | AR2: Commercial | AS2: Advanced Electrical Components | AT2: Advanced Electrical Components
A3: Rarity | AQ3: Green | AR3: Electrical | AS3: Advanced Mechanical Components | AT3: Advanced Mechanical Components
A4: Location | AQ4: NA | AR4: Exodus | AS4: Angled Grip I | AT4: Agave
A5: Used In | AQ5: Pink | AR5: Industrial | AS5: Antiseptic | AT5: Air Freshener
A6: Dismantles To | AQ6: Yellow | AR6: Mechanical | AS6: ARC Circuitry | AT6: Alarm Clock
A7: Show Unknown (NOT WORKING) | C7: FALSE | AR7: Medical | AS7: ARC Motion Core | AT7: Antiseptic
AR8: Nature | AS8: Arpeggio I | AT8: Apricot
A9: Component | B9: Rarity | C9: Price | D9: Total Needed | E9: Used For | F9: Locations | G9: Dismantles Into | AR9: Raider | AS9: Bandage | AT9: ARC Alloy
A10: {=_xlfn.LET(_xlpm.rarityFilter,IF(B3="","",B3),_xlpm.locationFilter,IF(B4="","",B4),_xlpm.stationFilter,IF(B5="","",B5),_xlpm.dismantleFilter,IF(B6="","",B6),_xlpm.showUnknown,C7,_xlpm.allCompIDs,tblComponent[ComponentID],_xlpm.allCompNames,tblComponent[ComponentName],_xlpm.rarityMatch,IF(_xlpm.rarityFilter="",1,(tblComponent[ComponentRarity]=_xlpm.rarityFilter)*1),_xlpm.locationIDs,IF(_xlpm.locationFilter="","",_xlfn.XLOOKUP(_xlpm.locationFilter,tblLocation[LocationName],tblLocation[LocationID])),_xlpm.locationMatch,IF(_xlpm.locationFilter="",1,(COUNTIFS(tblComponentLocation[ComponentID],_xlpm.allCompIDs,tblComponentLocation[LocationID],_xlpm.locationIDs)>0)*1),_xlpm.stationID,IF(_xlpm.stationFilter="","",_xlfn.XLOOKUP(_xlpm.stationFilter,tblCraftable[CraftableName],tblCraftable[CraftableID])),_xlpm.stationMatch,IF(_xlpm.stationFilter="",1,(COUNTIFS(tblComponentUsage[ComponentID],_xlpm.allCompIDs,tblComponentUsage[CraftableID],_xlpm.stationID)>0)*1),_xlpm.dismantleID,IF(_xlpm.dismantleFilter="","",_xlfn.XLOOKUP(_xlpm.dismantleFilter,tblComponent[ComponentName],tblComponent[ComponentID])),_xlpm.dismantleMatch,IF(_xlpm.dismantleFilter="",1,(COUNTIFS(tblDismantleResults[SourceComponentID],_xlpm.allCompIDs,tblDismantleResults[ResultComponentID],_xlpm.dismantleID)>0)*1),_xlpm.hasKnownLoc,_xlfn.MAP(tblComponent[ComponentID],_xlfn.LAMBDA(_xlpm.id,COUNTIFS(tblComponentLocation[ComponentID],_xlpm.id)>0)),_xlpm.showUnknownMatch,IF(_xlpm.showUnknown,1,_xlpm.hasKnownLoc*1),_xlpm.combinedMatch,_xlpm.rarityMatch*_xlpm.locationMatch*_xlpm.stationMatch*_xlpm.dismantleMatch*_xlpm.showUnknownMatch,_xlpm.resultName,_xlfn._xlws.FILTER(tblComponent[ComponentName],_xlpm.combinedMatch),_xlpm.resultRarity,_xlfn._xlws.FILTER(tblComponent[ComponentRarity],_xlpm.combinedMatch),_xlpm.resultPrice,_xlfn._xlws.FILTER(tblComponent[ComponentSellPrice],_xlpm.combinedMatch),_xlpm.resultTotalNeeded,_xlfn._xlws.FILTER(_xlfn.MAP(tblComponent[ComponentID],_xlfn.LAMBDA(_xlpm.id,SUMIFS(tblComponentUsage[UsageQuantity],tblComponentUsage[ComponentID],_xlpm.id))),_xlpm.combinedMatch),_xlpm.resultUses,_xlfn._xlws.FILTER(_xlfn.MAP(tblComponent[ComponentID],_xlfn.LAMBDA(_xlpm.id,_xlfn.LET(_xlpm.useIDs,IFERROR(_xlfn._xlws.FILTER(tblComponentUsage[CraftableID],tblComponentUsage[ComponentID]=_xlpm.id),""),_xlpm.useQtys,IFERROR(_xlfn._xlws.FILTER(tblComponentUsage[UsageQuantity],tblComponentUsage[ComponentID]=_xlpm.id),""),_xlpm.useNames,IF(OR(_xlpm.useIDs="",ROWS(_xlpm.useIDs)=0),"",IFERROR(_xlfn.XLOOKUP(_xlpm.useIDs,tblCraftable[CraftableID],tblCraftable[CraftableName]),"")),_xlpm.uses,IF(OR(_xlpm.useNames="",ROWS(_xlpm.useNames)=0),"No known use",_xlfn.TEXTJOIN(", ",TRUE,_xlpm.useNames&" ("&_xlpm.useQtys&")")),_xlpm.uses))),_xlpm.combinedMatch),_xlpm.resultLocations,_xlfn._xlws.FILTER(_xlfn.MAP(tblComponent[ComponentID],_xlfn.LAMBDA(_xlpm.id,_xlfn.LET(_xlpm.locs,IFERROR(_xlfn._xlws.FILTER(tblLocation[LocationName],ISNUMBER(MATCH(tblLocation[LocationID],_xlfn._xlws.FILTER(tblComponentLocation[LocationID],tblComponentLocation[ComponentID]=_xlpm.id),0))),""),IF(OR(_xlpm.locs="",ROWS(_xlpm.locs)=0),"Unknown",_xlfn.TEXTJOIN(", ",TRUE,_xlpm.locs))))),_xlpm.combinedMatch),_xlpm.resultDismantles,_xlfn._xlws.FILTER(_xlfn.MAP(tblComponent[ComponentID],_xlfn.LAMBDA(_xlpm.id,_xlfn.LET(_xlpm.disIDs,IFERROR(_xlfn._xlws.FILTER(tblDismantleResults[ResultComponentID],tblDismantleResults[SourceComponentID]=_xlpm.id),""),_xlpm.disQtys,IFERROR(_xlfn._xlws.FILTER(tblDismantleResults[Quantity],tblDismantleResults[SourceComponentID]=_xlpm.id),""),_xlpm.disNames,IF(OR(_xlpm.disIDs="",ROWS(_xlpm.disIDs)=0),"",IFERROR(_xlfn.XLOOKUP(_xlpm.disIDs,tblComponent[ComponentID],tblComponent[ComponentName]),"")),_xlpm.dismantleText,IF(OR(_xlpm.disNames="",ROWS(_xlpm.disNames)=0),"Cannot be dismantled",_xlfn.TEXTJOIN(", ",TRUE,_xlpm.disNames&" ("&_xlpm.disQtys&"x)")),_xlpm.dismantleText))),_xlpm.combinedMatch),IF(ROWS(_xlpm.resultName)=0,"No results found",_xlfn.HSTACK(_xlpm.resultName,_xlpm.resultRarity,_xlpm.resultPrice,_xlpm.resultTotalNeeded,_xlpm.resultUses,_xlpm.resultLocations,_xlpm.resultDismantles)))} -> Advanced ARC Powercell | B10: Blue | C10: 640 | D10: 1 | E10: Surge Shield Recharger (1) | F10: ARC | G10: Cannot be dismantled | AR10: Residential | AS10: Bettina I | AT10: ARC Circuitry
A11: Advanced Electrical Components | B11: Blue | C11: 1750 | D11: 17 | E11: Gear Bench (5), Utility Station (5), Looting Mk.3 (Cautious) (2), Power Rod (2), Photoelectric Cloak (2), Raider Hatch Key (1) | F11: Electrical | G11: Electrical Components (1x), Wires (1x) | AR11: Security | AS11: Binoculars | AT11: ARC Coolant
A12: Advanced Mechanical Components | B12: Blue | C12: 1750 | D12: 12 | E12: Gunsmith (5), Bettina I (3), Renegade I (2), Magnetic Accelerator (2) | F12: Mechanical | G12: Mechanical Components (1x), Wires (1x) | AR12: Technological | AS12: Combat Mk.1 | AT12: ARC Flex Rubber
A13: Agave | B13: Green | C13: 1000 | D13: 0 | E13: No known use | F13: Unknown | G13: Assorted Seeds (3x) | AS13: Combat Mk.2 | AT13: ARC Motion Core
A14: Air Freshener | B14: Gray | C14: 2000 | D14: 0 | E14: No known use | F14: Unknown | G14: Cannot be dismantled | AS14: Compensator I | AT14: ARC Performance Steel
A15: Alarm Clock | B15: Blue | C15: 1000 | D15: 0 | E15: No known use | F15: Unknown | G15: Processor (1x), Plastic Parts (6x) | AS15: Crude Explosives | AT15: ARC Powercell
A16: Antiseptic | B16: Blue | C16: 1000 | D16: 9 | E16: Medical Lab (8), Sterilized Bandage (1) | F16: Medical | G16: Chemicals (10x) | AS16: Door Blocker | AT16: ARC Synthetic Resin
A17: Apricot | B17: Green | C17: 640 | D17: 15 | E17: Scrappy (3), Scrappy (12) | F17: Nature | G17: Assorted Seeds (3x) | AS17: Durable Cloth | AT17: ARC Thermo Lining
A18: ARC Alloy | B18: Green | C18: 200 | D18: 32 | E18: Explosives Station (6), Medical Lab (6), Utility Station (6), Light Shield (2), ARC Circuitry (6), ARC Motion Core (6) | F18: ARC | G18: Metal Parts (2x) | AS18: Electrical Components | AT18: Assorted Seeds
A19: ARC Circuitry | B19: Blue | C19: 1000 | D19: 13 | E19: Refiner (10), Medium Shield (1), Power Rod (2) | F19: ARC | G19: ARC Alloy (2x) | AS19: Explosive Compound | AT19: Bastion Cell
A20: ARC Coolant | B20: Blue | C20: 1000 | D20: 0 | E20: No known use | F20: Unknown | G20: Chemicals (16x) | AS20: Explosives Station | AT20: Battery
A21: ARC Flex Rubber | B21: Blue | C21: 1000 | D21: 0 | E21: No known use | F21: ARC | G21: Rubber Parts (16x) | AS21: Extended Light Mag I | AT21: Bicycle Pump
A22: ARC Motion Core | B22: Blue | C22: 1000 | D22: 7 | E22: Refiner (5), Magnetic Accelerator (2) | F22: ARC | G22: ARC Alloy (2x) | AS22: Extended Medium Mag I | AT22: Bloated Tuna Can
A23: ARC Performance Steel | B23: Blue | C23: 1000 | D23: 0 | E23: No known use | F23: ARC | G23: Metal Parts (12x) | AS23: Extended Shotgun Mag I | AT23: Blown Fuses
A24: ARC Powercell | B24: Gray | C24: 640 | D24: 6 | E24: Refiner (5), Shield Recharger (1) | F24: ARC | G24: Cannot be dismantled | AS24: Ferro I | AT24: Bombardier Cell
... A31: Bloated Tuna Can | B31: Gray | C31: 1000 | D31: 0 | E31: No known use | F31: Unknown | G31: Cannot be dismantled | AS31: Heavy Shield | AT31: Camera Lens
A32: Blown Fuses | B32: Gray | C32: NA | D32: 0 | E32: No known use | F32: Unknown | G32: Cannot be dismantled | AS32: Herbal Bandage | AT32: Candle Holder
A33: Bombardier Cell | B33: Pink | C33: 5000 | D33: 6 | E33: Refiner (6) | F33: Unknown | G33: Advanced Mechanical Components (2x), ARC Alloy (2x) | AS33: Kettle I | AT33: Canister
A34: Breathtaking Snow Globe | B34: Pink | C34: 7000 | D34: 0 | E34: No known use | F34: Unknown | G34: Cannot be dismantled | AS34: Light Ammo | AT34: Cat Bed
A35: Broken Flashlight | B35: Blue | C35: 1000 | D35: 0 | E35: No known use | F35: Unknown | G35: Battery (3x), Metal Parts (7x) | AS35: Light Impact Grenade | AT35: Chemicals
A36: Broken Handheld Radio | B36: Blue | C36: 1000 | D36: 0 | E36: No known use | F36: Unknown | G36: Sensors (3x), Wires (3x) | AS36: Light Shield | AT36: Coffee Pot
A37: Broken Riot Shield | B37: Blue | C37: NA | D37: 0 | E37: No known use | F37: Unknown | G37: Plastic Parts (12x) | AS37: Li'l Smoke Grenade | AT37: Complex Gun Parts
A38: Broken Taser | B38: Blue | C38: 1000 | D38: 0 | E38: No known use | F38: Unknown | G38: Battery (2x), Wires (2x) | AS38: Looting Mk.1 | AT38: Coolant
A39: Burned ARC Circuitry | B39: Green | C39: 640 | D39: 0 | E39: No known use | F39: Unknown | G39: ARC Alloy (2x) | AS39: Looting Mk.2 | AT39: Cooling Coil
A40: Camera Lens | B40: Green | C40: 640 | D40: 0 | E40: No known use | F40: Unknown | G40: Plastic Parts (8x) | AS40: Looting Mk.3 (Cautious) | AT40: Cooling Fan
A41: Candle Holder | B41: Green | C41: 270 | D41: 0 | E41: No known use | F41: Unknown | G41: Metal Parts (8x) | AS41: Lure Grenade | AT41: Cracked Bioscanner
A42: Canister | B42: Green | C42: 300 | D42: 5 | E42: Bettina I (3), Heavy Fuze Grenade (2) | F42: Commercial | G42: Plastic Parts (3x) | AS42: Magnetic Accelerator | AT42: Crude Explosives
A43: Cat Bed | B43: Gray | C43: 1000 | D43: 1 | E43: Scrappy (1) | F43: Commercial, Residential | G43: Cannot be dismantled | AS43: Mechanical Components | AT43: Crumpled Plastic Bottle
A44: Chemicals | B44: Gray | C44: 50 | D44: 92 | E44: Explosives Station (50), Heavy Ammo (2), Light Ammo (2), Medium Ammo (2), Shotgun Ammo (2), Light Impact Grenade (3), Antiseptic (10), Crude Explosives (6), Gas Grenade (4), Light Impact Grenade (3), Adrenaline Shot (3), Li'l Smoke Grenade (5) | F44: Mechanical, Medical, Residential | G44: Cannot be dismantled | AS44: Medical Lab | AT44: Damaged ARC Motion Core
A45: Coffee Pot | B45: Gray | C45: 2000 | D45: 0 | E45: No known use | F45: Unknown | G45: Cannot be dismantled | AS45: Medium Ammo | AT45: Damaged ARC Powercell
A46: Complex Gun Parts | B46: Pink | C46: 1000 | D46: 0 | E46: No known use | F46: Security | G46: Simple Gun Parts (3x) | AS46: Medium Shield | AT46: Damaged Fireball Burner
...

Sheet 01_Craftable
A1: numeric | B1: CraftableID | C1: CraftableName
A2: 001 | B2: CRFT-001 | C2: Explosives Station
A3: 002 | B3: CRFT-002 | C3: Gear Bench
A4: 003 | B4: CRFT-003 | C4: Gunsmith
A5: 004 | B5: CRFT-004 | C5: Medical Lab
A6: 005 | B6: CRFT-005 | C6: Refiner
A7: 006 | B7: CRFT-006 | C7: Scrappy
A8: 007 | B8: CRFT-007 | C8: Utility Station
A9: 008 | B9: =_xlfn.CONCAT("CRFT-",A9) -> CRFT-008 | C9: Looting Mk.1
A10: 009 | B10: =_xlfn.CONCAT("CRFT-",A10) -> CRFT-009 | C10: Light Shield
A11: 010 | B11: =_xlfn.CONCAT("CRFT-",A11) -> CRFT-010 | C11: Ferro I
A12: 011 | B12: =_xlfn.CONCAT("CRFT-",A12) -> CRFT-011 | C12: Hairpin I
A13: 012 | B13: =_xlfn.CONCAT("CRFT-",A13) -> CRFT-012 | C13: Kettle I
A14: 013 | B14: =_xlfn.CONCAT("CRFT-",A14) -> CRFT-013 | C14: Stitcher I
A15: 014 | B15: =_xlfn.CONCAT("CRFT-",A15) -> CRFT-014 | C15: Heavy Ammo
A16: 015 | B16: =_xlfn.CONCAT("CRFT-",A16) -> CRFT-015 | C16: Light Ammo
A17: 016 | B17: =_xlfn.CONCAT("CRFT-",A17) -> CRFT-016 | C17: Medium Ammo
A18: 017 | B18: =_xlfn.CONCAT("CRFT-",A18) -> CRFT-017 | C18: Shotgun Ammo
A19: 018 | B19: =_xlfn.CONCAT("CRFT-",A19) -> CRFT-018 | C19: Light Impact Grenade
A20: 019 | B20: =_xlfn.CONCAT("CRFT-",A20) -> CRFT-019 | C20: Shield Recharger
... A72: 071 | B72: =_xlfn.CONCAT("CRFT-",A72) -> CRFT-071 | C72: Zipline

Sheet 02_Location
A1: LocationID | B1: LocationName
A2: LOC-001 | B2: ARC
A3: LOC-002 | B3: Commercial
A4: LOC-003 | B4: Electrical
A5: LOC-004 | B5: Exodus
A6: LOC-005 | B6: Industrial
A7: LOC-006 | B7: Mechanical
A8: LOC-007 | B8: Medical
A9: LOC-008 | B9: Nature
A10: LOC-009 | B10: Residential
A11: LOC-010 | B11: Security
A12: LOC-011 | B12: Technological
A13: LOC-012 | B13: Raider

Sheet 03_Component
A1: Numeric | B1: ComponentID | C1: ComponentName | D1: ComponentRarity | E1: ComponentSellPrice
A2: 001 | B2: COMP-001 | C2: Advanced ARC Powercell | D2: Blue | E2: 640
A3: 002 | B3: COMP-002 | C3: Advanced Electrical Components | D3: Blue | E3: 1750
A4: 003 | B4: COMP-003 | C4: Advanced Mechanical Components | D4: Blue | E4: 1750
A5: 004 | B5: COMP-004 | C5: Agave | D5: Green | E5: 1000
A6: 005 | B6: COMP-005 | C6: Air Freshener | D6: Gray | E6: 2000
A7: 006 | B7: COMP-006 | C7: Alarm Clock | D7: Blue | E7: 1000
A8: 007 | B8: COMP-007 | C8: Antiseptic | D8: Blue | E8: 1000
A9: 008 | B9: COMP-008 | C9: Apricot | D9: Green | E9: 640
A10: 009 | B10: COMP-009 | C10: ARC Alloy | D10: Green | E10: 200
A11: 010 | B11: COMP-010 | C11: ARC Circuitry | D11: Blue | E11: 1000
A12: 011 | B12: COMP-011 | C12: ARC Coolant | D12: Blue | E12: 1000
A13: 012 | B13: COMP-012 | C13: ARC Flex Rubber | D13: Blue | E13: 1000
... A23: 022 | B23: COMP-022 | C23: Bloated Tuna Can | D23: Gray | E23: 1000
A24: 023 | B24: COMP-023 | C24: Blown Fuses | D24: Gray | E24: NA
A25: 024 | B25: COMP-024 | C25: Bombardier Cell | D25: Pink | E25: 5000
A26: 025 | B26: COMP-025 | C26: Breathtaking Snow Globe | D26: Pink | E26: 7000
A27: 026 | B27: COMP-026 | C27: Broken Flashlight | D27: Blue | E27: 1000
A28: 027 | B28: COMP-027 | C28: Broken Handheld Radio | D28: Blue | E28: 1000
A29: 028 | B29: COMP-028 | C29: Broken Riot Shield | D29: Blue | E29: NA
A30: 029 | B30: COMP-029 | C30: Broken Taser | D30: Blue | E30: 1000
A31: 030 | B31: COMP-030 | C31: Burned ARC Circuitry | D31: Green | E31: 640
A32: 031 | B32: COMP-031 | C32: Camera Lens | D32: Green | E32: 640
A33: 032 | B33: COMP-032 | C33: Candle Holder | D33: Green | E33: 270
A34: 033 | B34: COMP-033 | C34: Canister | D34: Green | E34: 300
A35: 034 | B35: COMP-034 | C35: Cat Bed | D35: Gray | E35: 1000
A36: 035 | B36: COMP-035 | C36: Chemicals | D36: Gray | E36: 50
A37: 036 | B37: COMP-036 | C37: Coffee Pot | D37: Gray | E37: 2000
A38: 037 | B38: COMP-037 | C38: Complex Gun Parts | D38: Pink | E38: 1000
A39: 038 | B39: COMP-038 | C39: Coolant | D39: Blue | E39: 1000
A40: 039 | B40: COMP-039 | C40: Cooling Coil | D40: Blue | E40: 1000
A41: 040 | B41: COMP-040 | C41: Cooling Fan | D41: Blue | E41: 2000
... A176: 175 | B176: COMP-175 | C176: Wires | D176: Green | E176: 200

Sheet 04_ComponentUsage
A1: UsageID | B1: ComponentID | C1: CraftableID | D1: UsageQuantity | F1: Component Name (Plaintext) | G1: Craftable Name (Plaintext)
A2: USE-001 | B2: =_xlfn.XLOOKUP($F2,'03_Component'!$C:$C,'03_Component'!$B:$B) -> COMP-009 | C2: =_xlfn.XLOOKUP($G2,'01_Craftable'!$C:$C,'01_Craftable'!$B:$B) -> CRFT-001 | D2: 6 | F2: ARC Alloy | G2: Explosives Station
A3: USE-002 | B3: =_xlfn.XLOOKUP($F3,'03_Component'!$C:$C,'03_Component'!$B:$B) -> COMP-035 | C3: =_xlfn.XLOOKUP($G3,'01_Craftable'!$C:$C,'01_Craftable'!$B:$B) -> CRFT-001 | D3: 50 | F3: Chemicals | G3: Explosives Station
A4: USE-003 | B4: =_xlfn.XLOOKUP($F4,'03_Component'!$C:$C,'03_Component'!$B:$B) -> COMP-042 | C4: =_xlfn.XLOOKUP($G4,'01_Craftable'!$C:$C,'01_Craftable'!$B:$B) -> CRFT-001 | D4: 5 | F4: Crude Explosives | G4: Explosives Station
A5: USE-004 | B5: =_xlfn.XLOOKUP($F5,'03_Component'!$C:$C,'03_Component'!$B:$B) -> COMP-064 | C5: =_xlfn.XLOOKUP($G5,'01_Craftable'!$C:$C,'01_Craftable'!$B:$B) -> CRFT-001 | D5: 5 | F5: Explosive Compound | G5: Explosives Station
A6: USE-005 | B6: =_xlfn.XLOOKUP($F6,'03_Component'!$C:$C,'03_Component'!$B:$B) -> COMP-085 | C6: =_xlfn.XLOOKUP($G6,'01_Craftable'!$C:$C,'01_Craftable'!$B:$B) -> CRFT-001 | D6: 3 | F6: Laboratory Reagents | G6: Explosives Station
A7: USE-006 | B7: =_xlfn.XLOOKUP($F7,'03_Component'!$C:$C,'03_Component'!$B:$B) -> COMP-110 | C7: =_xlfn.XLOOKUP($G7,'01_Craftable'!$C:$C,'01_Craftable'!$B:$B) -> CRFT-001 | D7: 5 | F7: Pop Trigger | G7: Explosives Station
A8: USE-007 | B8: =_xlfn.XLOOKUP($F8,'03_Component'!$C:$C,'03_Component'!$B:$B) -> COMP-125 | C8: =_xlfn.XLOOKUP($G8,'01_Craftable'!$C:$C,'01_Craftable'!$B:$B) -> CRFT-001 | D8: 3 | F8: Rocketeer Driver | G8: Explosives Station
A9: USE-008 | B9: =_xlfn.XLOOKUP($F9,'03_Component'!$C:$C,'03_Component'!$B:$B) -> COMP-157 | C9: =_xlfn.XLOOKUP($G9,'01_Craftable'!$C:$C,'01_Craftable'!$B:$B) -> CRFT-001 | D9: 3 | F9: Synthesized Fuel | G9: Explosives Station
A10: USE-009 | B10: =_xlfn.XLOOKUP($F10,'03_Component'!$C:$C,'03_Component'!$B:$B) -> COMP-002 | C10: =_xlfn.XLOOKUP($G10,'01_Craftable'!$C:$C,'01_Craftable'!$B:$B) -> CRFT-002 | D10: 5 | F10: Advanced Electrical Components | G10: Gear Bench
A11: USE-010 | B11: =_xlfn.XLOOKUP($F11,'03_Component'!$C:$C,'03_Component'!$B:$B) -> COMP-019 | C11: =_xlfn.XLOOKUP($G11,'01_Craftable'!$C:$C,'01_Craftable'!$B:$B) -> CRFT-002 | D11: 6 | F11: Bastion Cell | G11: Gear Bench
A12: USE-011 | B12: =_xlfn.XLOOKUP($F12,'03_Component'!$C:$C,'03_Component'!$B:$B) -> COMP-059 | C12: =_xlfn.XLOOKUP($G12,'01_Craftable'!$C:$C,'01_Craftable'!$B:$B) -> CRFT-002 | D12: 5 | F12: Electrical Components | G12: Gear Bench
A13: USE-012 | B13: =_xlfn.XLOOKUP($F13,'03_Component'!$C:$C,'03_Component'!$B:$B) -> COMP-065 | C13: =_xlfn.XLOOKUP($G13,'01_Craftable'!$C:$C,'01_Craftable'!$B:$B) -> CRFT-002 | D13: 30 | F13: Fabric | G13: Gear Bench
... A58: USE-057 | B58: =_xlfn.XLOOKUP($F58,'03_Component'!$C:$C,'03_Component'!$B:$B) -> COMP-150 | C58: =_xlfn.XLOOKUP($G58,'01_Craftable'!$C:$C,'01_Craftable'!$B:$B) -> CRFT-007 | D58: 6 | F58: Snitch Scanner | G58: Utility Station
A59: {="USE-" & TEXT(ROW()-ROW(tblComponentUsage[#Headers]),"000")} -> USE-058 | B59: =_xlfn.XLOOKUP($F59,'03_Component'!$C:$C,'03_Component'!$B:$B) -> COMP-107 | C59: =_xlfn.XLOOKUP($G59,'01_Craftable'!$C:$C,'01_Craftable'!$B:$B) -> CRFT-008 | D59: 6 | F59: Plastic Parts | G59: Looting Mk.1
A60: {="USE-" & TEXT(ROW()-ROW(tblComponentUsage[#Headers]),"000")} -> USE-059 | B60: =_xlfn.XLOOKUP($F60,'03_Component'!$C:$C,'03_Component'!$B:$B) -> COMP-133 | C60: =_xlfn.XLOOKUP($G60,'01_Craftable'!$C:$C,'01_Craftable'!$B:$B) -> CRFT-008 | D60: 6 | F60: Rubber Parts | G60: Looting Mk.1
A61: {="USE-" & TEXT(ROW()-ROW(tblComponentUsage[#Headers]),"000")} -> USE-060 | B61: =_xlfn.XLOOKUP($F61,'03_Component'!$C:$C,'03_Component'!$B:$B) -> COMP-009 | C61: =_xlfn.XLOOKUP($G61,'01_Craftable'!$C:$C,'01_Craftable'!$B:$B) -> CRFT-009 | D61: 2 | F61: ARC Alloy | G61: Light Shield
A62: {="USE-" & TEXT(ROW()-ROW(tblComponentUsage[#Headers]),"000")} -> USE-061 | B62: =_xlfn.XLOOKUP($F62,'03_Component'!$C:$C,'03_Component'!$B:$B) -> COMP-107 | C62: =_xlfn.XLOOKUP($G62,'01_Craftable'!$C:$C,'01_Craftable'!$B:$B) -> CRFT-009 | D62: 4 | F62: Plastic Parts | G62: Light Shield
A63: {="USE-" & TEXT(ROW()-ROW(tblComponentUsage[#Headers]),"000")} -> USE-062 | B63: =_xlfn.XLOOKUP($F63,'03_Component'!$C:$C,'03_Component'!$B:$B) -> COMP-096 | C63: =_xlfn.XLOOKUP($G63,'01_Craftable'!$C:$C,'01_Craftable'!$B:$B) -> CRFT-010 | D63: 5 | F63: Metal Parts | G63: Ferro I
A64: {="USE-" & TEXT(ROW()-ROW(tblComponentUsage[#Headers]),"000")} -> USE-063 | B64: =_xlfn.XLOOKUP($F64,'03_Component'!$C:$C,'03_Component'!$B:$B) -> COMP-133 | C64: =_xlfn.XLOOKUP($G64,'01_Craftable'!$C:$C,'01_Craftable'!$B:$B) -> CRFT-010 | D64: 2 | F64: Rubber Parts | G64: Ferro I
A65: {="USE-" & TEXT(ROW()-ROW(tblComponentUsage[#Headers]),"000")} -> USE-064 | B65: =_xlfn.XLOOKUP($F65,'03_Component'!$C:$C,'03_Component'!$B:$B) -> COMP-096 | C65: =_xlfn.XLOOKUP($G65,'01_Craftable'!$C:$C,'01_Craftable'!$B:$B) -> CRFT-011 | D65: 2 | F65: Metal Parts | G65: Hairpin I
A66: {="USE-" & TEXT(ROW()-ROW(tblComponentUsage[#Headers]),"000")} -> USE-065 | B66: =_xlfn.XLOOKUP($F66,'03_Component'!$C:$C,'03_Component'!$B:$B) -> COMP-107 | C66: =_xlfn.XLOOKUP($G66,'01_Craftable'!$C:$C,'01_Craftable'!$B:$B) -> CRFT-011 | D66: 5 | F66: Plastic Parts | G66: Hairpin I
A67: {="USE-" & TEXT(ROW()-ROW(tblComponentUsage[#Headers]),"000")} -> USE-066 | B67: =_xlfn.XLOOKUP($F67,'03_Component'!$C:$C,'03_Component'!$B:$B) -> COMP-096 | C67: =_xlfn.XLOOKUP($G67,'01_Craftable'!$C:$C,'01_Craftable'!$B:$B) -> CRFT-012 | D67: 6 | F67: Metal Parts | G67: Kettle I
A68: {="USE-" & TEXT(ROW()-ROW(tblComponentUsage[#Headers]),"000")} -> USE-067 | B68: =_xlfn.XLOOKUP($F68,'03_Component'!$C:$C,'03_Component'!$B:$B) -> COMP-133 | C68: =_xlfn.XLOOKUP($G68,'01_Craftable'!$C:$C,'01_Craftable'!$B:$B) -> CRFT-012 | D68: 8 | F68: Rubber Parts | G68: Kettle I
A69: {="USE-" & TEXT(ROW()-ROW(tblComponentUsage[#Headers]),"000")} -> USE-068 | B69: =_xlfn.XLOOKUP($F69,'03_Component'!$C:$C,'03_Component'!$B:$B) -> COMP-096 | C69: =_xlfn.XLOOKUP($G69,'01_Craftable'!$C:$C,'01_Craftable'!$B:$B) -> CRFT-013 | D69: 8 | F69: Metal Parts | G69: Stitcher I
A70: {="USE-" & TEXT(ROW()-ROW(tblComponentUsage[#Headers]),"000")} -> USE-069 | B70: =_xlfn.XLOOKUP($F70,'03_Component'!$C:$C,'03_Component'!$B:$B) -> COMP-133 | C70: =_xlfn.XLOOKUP($G70,'01_Craftable'!$C:$C,'01_Craftable'!$B:$B) -> CRFT-013 | D70: 4 | F70: Rubber Parts | G70: Stitcher I
... A183: {="USE-" & TEXT(ROW()-ROW(tblComponentUsage[#Headers]),"000")} -> USE-182 | B183: =_xlfn.XLOOKUP($F183,'03_Component'!$C:$C,'03_Component'!$B:$B) -> COMP-093 | C183: =_xlfn.XLOOKUP($G183,'01_Craftable'!$C:$C,'01_Craftable'!$B:$B) -> CRFT-071 | D183: 1 | F183: Mechanical Components | G183: Zipline

Sheet 05_ComponentLocation
A1: numeric | B1: CompLocID | C1: ComponentID | D1: LocationID | F1: Component Name (Plaintext) | G1: Location Name (Plaintext)
A2: 001 | B2: =_xlfn.CONCAT("CL-",A2) -> CL-001 | C2: =_xlfn.XLOOKUP($F2,'03_Component'!$C:$C,'03_Component'!$B:$B) -> COMP-001 | D2: =_xlfn.XLOOKUP($G2,'02_Location'!$B:$B,'02_Location'!$A:$A) -> LOC-001 | F2: Advanced ARC Powercell | G2: ARC
A3: 002 | B3: =_xlfn.CONCAT("CL-",A3) -> CL-002 | C3: =_xlfn.XLOOKUP($F3,'03_Component'!$C:$C,'03_Component'!$B:$B) -> COMP-002 | D3: =_xlfn.XLOOKUP($G3,'02_Location'!$B:$B,'02_Location'!$A:$A) -> LOC-003 | F3: Advanced Electrical Components | G3: Electrical
A4: 003 | B4: =_xlfn.CONCAT("CL-",A4) -> CL-003 | C4: =_xlfn.XLOOKUP($F4,'03_Component'!$C:$C,'03_Component'!$B:$B) -> COMP-003 | D4: =_xlfn.XLOOKUP($G4,'02_Location'!$B:$B,'02_Location'!$A:$A) -> LOC-006 | F4: Advanced Mechanical Components | G4: Mechanical
A5: 004 | B5: =_xlfn.CONCAT("CL-",A5) -> CL-004 | C5: =_xlfn.XLOOKUP($F5,'03_Component'!$C:$C,'03_Component'!$B:$B) -> COMP-004 | D5: =_xlfn.XLOOKUP($G5,'02_Location'!$B:$B,'02_Location'!$A:$A) -> 0 | F5: Agave
A6: 005 | B6: =_xlfn.CONCAT("CL-",A6) -> CL-005 | C6: =_xlfn.XLOOKUP($F6,'03_Component'!$C:$C,'03_Component'!$B:$B) -> COMP-005 | D6: =_xlfn.XLOOKUP($G6,'02_Location'!$B:$B,'02_Location'!$A:$A) -> 0 | F6: Air Freshener
A7: 006 | B7: =_xlfn.CONCAT("CL-",A7) -> CL-006 | C7: =_xlfn.XLOOKUP($F7,'03_Component'!$C:$C,'03_Component'!$B:$B) -> COMP-006 | D7: =_xlfn.XLOOKUP($G7,'02_Location'!$B:$B,'02_Location'!$A:$A) -> 0 | F7: Alarm Clock
A8: 007 | B8: =_xlfn.CONCAT("CL-",A8) -> CL-007 | C8: =_xlfn.XLOOKUP($F8,'03_Component'!$C:$C,'03_Component'!$B:$B) -> COMP-007 | D8: =_xlfn.XLOOKUP($G8,'02_Location'!$B:$B,'02_Location'!$A:$A) -> LOC-007 | F8: Antiseptic | G8: Medical
A9: 008 | B9: =_xlfn.CONCAT("CL-",A9) -> CL-008 | C9: =_xlfn.XLOOKUP($F9,'03_Component'!$C:$C,'03_Component'!$B:$B) -> COMP-008 | D9: =_xlfn.XLOOKUP($G9,'02_Location'!$B:$B,'02_Location'!$A:$A) -> LOC-008 | F9: Apricot | G9: Nature
A10: 009 | B10: =_xlfn.CONCAT("CL-",A10) -> CL-009 | C10: =_xlfn.XLOOKUP($F10,'03_Component'!$C:$C,'03_Component'!$B:$B) -> COMP-009 | D10: =_xlfn.XLOOKUP($G10,'02_Location'!$B:$B,'02_Location'!$A:$A) -> LOC-001 | F10: ARC Alloy | G10: ARC
A11: 010 | B11: =_xlfn.CONCAT("CL-",A11) -> CL-010 | C11: =_xlfn.XLOOKUP($F11,'03_Component'!$C:$C,'03_Component'!$B:$B) -> COMP-010 | D11: =_xlfn.XLOOKUP($G11,'02_Location'!$B:$B,'02_Location'!$A:$A) -> LOC-001 | F11: ARC Circuitry | G11: ARC
A12: 011 | B12: =_xlfn.CONCAT("CL-",A12) -> CL-011 | C12: =_xlfn.XLOOKUP($F12,'03_Component'!$C:$C,'03_Component'!$B:$B) -> COMP-011 | D12: =_xlfn.XLOOKUP($G12,'02_Location'!$B:$B,'02_Location'!$A:$A) -> 0 | F12: ARC Coolant
A13: 012 | B13: =_xlfn.CONCAT("CL-",A13) -> CL-012 | C13: =_xlfn.XLOOKUP($F13,'03_Component'!$C:$C,'03_Component'!$B:$B) -> COMP-012 | D13: =_xlfn.XLOOKUP($G13,'02_Location'!$B:$B,'02_Location'!$A:$A) -> LOC-001 | F13: ARC Flex Rubber | G13: ARC
A14: 013 | B14: =_xlfn.CONCAT("CL-",A14) -> CL-013 | C14: =_xlfn.XLOOKUP($F14,'03_Component'!$C:$C,'03_Component'!$B:$B) -> COMP-013 | D14: =_xlfn.XLOOKUP($G14,'02_Location'!$B:$B,'02_Location'!$A:$A) -> LOC-001 | F14: ARC Motion Core | G14: ARC
A15: 014 | B15: =_xlfn.CONCAT("CL-",A15) -> CL-014 | C15: =_xlfn.XLOOKUP($F15,'03_Component'!$C:$C,'03_Component'!$B:$B) -> COMP-014 | D15: =_xlfn.XLOOKUP($G15,'02_Location'!$B:$B,'02_Location'!$A:$A) -> LOC-001 | F15: ARC Performance Steel | G15: ARC
A16: 015 | B16: =_xlfn.CONCAT("CL-",A16) -> CL-015 | C16: =_xlfn.XLOOKUP($F16,'03_Component'!$C:$C,'03_Component'!$B:$B) -> COMP-015 | D16: =_xlfn.XLOOKUP($G16,'02_Location'!$B:$B,'02_Location'!$A:$A) -> LOC-001 | F16: ARC Powercell | G16: ARC
A17: 016 | B17: =_xlfn.CONCAT("CL-",A17) -> CL-016 | C17: =_xlfn.XLOOKUP($F17,'03_Component'!$C:$C,'03_Component'!$B:$B) -> COMP-016 | D17: =_xlfn.XLOOKUP($G17,'02_Location'!$B:$B,'02_Location'!$A:$A) -> LOC-001 | F17: ARC Synthetic Resin | G17: ARC
A18: 017 | B18: =_xlfn.CONCAT("CL-",A18) -> CL-017 | C18: =_xlfn.XLOOKUP($F18,'03_Component'!$C:$C,'03_Component'!$B:$B) -> COMP-017 | D18: =_xlfn.XLOOKUP($G18,'02_Location'!$B:$B,'02_Location'!$A:$A) -> LOC-001 | F18: ARC Thermo Lining | G18: ARC
A19: 018 | B19: =_xlfn.CONCAT("CL-",A19) -> CL-018 | C19: =_xlfn.XLOOKUP($F19,'03_Component'!$C:$C,'03_Component'!$B:$B) -> COMP-018 | D19: =_xlfn.XLOOKUP($G19,'02_Location'!$B:$B,'02_Location'!$A:$A) -> LOC-008 | F19: Assorted Seeds | G19: Nature
A20: 019 | B20: =_xlfn.CONCAT("CL-",A20) -> CL-019 | C20: =_xlfn.XLOOKUP($F20,'03_Component'!$C:$C,'03_Component'!$B:$B) -> COMP-019 | D20: =_xlfn.XLOOKUP($G20,'02_Location'!$B:$B,'02_Location'!$A:$A) -> 0 | F20: Bastion Cell
A21: 020 | B21: =_xlfn.CONCAT("CL-",A21) -> CL-020 | C21: =_xlfn.XLOOKUP($F21,'03_Component'!$C:$C,'03_Component'!$B:$B) -> COMP-020 | D21: =_xlfn.XLOOKUP($G21,'02_Location'!$B:$B,'02_Location'!$A:$A) -> LOC-011 | F21: Battery | G21: Technological
A22: 021 | B22: =_xlfn.CONCAT("CL-",A22) -> CL-021 | C22: =_xlfn.XLOOKUP($F22,'03_Component'!$C:$C,'03_Component'!$B:$B) -> COMP-020 | D22: =_xlfn.XLOOKUP($G22,'02_Location'!$B:$B,'02_Location'!$A:$A) -> LOC-003 | F22: Battery | G22: Electrical
A23: 022 | B23: =_xlfn.CONCAT("CL-",A23) -> CL-022 | C23: =_xlfn.XLOOKUP($F23,'03_Component'!$C:$C,'03_Component'!$B:$B) -> COMP-021 | D23: =_xlfn.XLOOKUP($G23,'02_Location'!$B:$B,'02_Location'!$A:$A) -> 0 | F23: Bicycle Pump
A24: 023 | B24: =_xlfn.CONCAT("CL-",A24) -> CL-023 | C24: =_xlfn.XLOOKUP($F24,'03_Component'!$C:$C,'03_Component'!$B:$B) -> COMP-022 | D24: =_xlfn.XLOOKUP($G24,'02_Location'!$B:$B,'02_Location'!$A:$A) -> 0 | F24: Bloated Tuna Can
A25: 024 | B25: =_xlfn.CONCAT("CL-",A25) -> CL-024 | C25: =_xlfn.XLOOKUP($F25,'03_Component'!$C:$C,'03_Component'!$B:$B) -> COMP-023 | D25: =_xlfn.XLOOKUP($G25,'02_Location'!$B:$B,'02_Location'!$A:$A) -> 0 | F25: Blown Fuses
A26: 025 | B26: =_xlfn.CONCAT("CL-",A26) -> CL-025 | C26: =_xlfn.XLOOKUP($F26,'03_Component'!$C:$C,'03_Component'!$B:$B) -> COMP-024 | D26: =_xlfn.XLOOKUP($G26,'02_Location'!$B:$B,'02_Location'!$A:$A) -> 0 | F26: Bombardier Cell
A27: 026 | B27: =_xlfn.CONCAT("CL-",A27) -> CL-026 | C27: =_xlfn.XLOOKUP($F27,'03_Component'!$C:$C,'03_Component'!$B:$B) -> COMP-025 | D27: =_xlfn.XLOOKUP($G27,'02_Location'!$B:$B,'02_Location'!$A:$A) -> 0 | F27: Breathtaking Snow Globe
A28: 027 | B28: =_xlfn.CONCAT("CL-",A28) -> CL-027 | C28: =_xlfn.XLOOKUP($F28,'03_Component'!$C:$C,'03_Component'!$B:$B) -> COMP-026 | D28: =_xlfn.XLOOKUP($G28,'02_Location'!$B:$B,'02_Location'!$A:$A) -> 0 | F28: Broken Flashlight
A29: 028 | B29: =_xlfn.CONCAT("CL-",A29) -> CL-028 | C29: =_xlfn.XLOOKUP($F29,'03_Component'!$C:$C,'03_Component'!$B:$B) -> COMP-027 | D29: =_xlfn.XLOOKUP($G29,'02_Location'!$B:$B,'02_Location'!$A:$A) -> 0 | F29: Broken Handheld Radio
A30: 029 | B30: =_xlfn.CONCAT("CL-",A30) -> CL-029 | C30: =_xlfn.XLOOKUP($F30,'03_Component'!$C:$C,'03_Component'!$B:$B) -> COMP-028 | D30: =_xlfn.XLOOKUP($G30,'02_Location'!$B:$B,'02_Location'!$A:$A) -> 0 | F30: Broken Riot Shield
A31: 030 | B31: =_xlfn.CONCAT("CL-",A31) -> CL-030 | C31: =_xlfn.XLOOKUP($F31,'03_Component'!$C:$C,'03_Component'!$B:$B) -> COMP-029 | D31: =_xlfn.XLOOKUP($G31,'02_Location'!$B:$B,'02_Location'!$A:$A) -> 0 | F31: Broken Taser
A32: 031 | B32: =_xlfn.CONCAT("CL-",A32) -> CL-031 | C32: =_xlfn.XLOOKUP($F32,'03_Component'!$C:$C,'03_Component'!$B:$B) -> COMP-030 | D32: =_xlfn.XLOOKUP($G32,'02_Location'!$B:$B,'02_Location'!$A:$A) -> 0 | F32: Burned ARC Circuitry
A33: 032 | B33: =_xlfn.CONCAT("CL-",A33) -> CL-032 | C33: =_xlfn.XLOOKUP($F33,'03_Component'!$C:$C,'03_Component'!$B:$B) -> COMP-031 | D33: =_xlfn.XLOOKUP($G33,'02_Location'!$B:$B,'02_Location'!$A:$A) -> 0 | F33: Camera Lens
A34: 033 | B34: =_xlfn.CONCAT("CL-",A34) -> CL-033 | C34: =_xlfn.XLOOKUP($F34,'03_Component'!$C:$C,'03_Component'!$B:$B) -> COMP-032 | D34: =_xlfn.XLOOKUP($G34,'02_Location'!$B:$B,'02_Location'!$A:$A) -> 0 | F34: Candle Holder
A35: 034 | B35: =_xlfn.CONCAT("CL-",A35) -> CL-034 | C35: =_xlfn.XLOOKUP($F35,'03_Component'!$C:$C,'03_Component'!$B:$B) -> COMP-033 | D35: =_xlfn.XLOOKUP($G35,'02_Location'!$B:$B,'02_Location'!$A:$A) -> LOC-002 | F35: Canister | G35: Commercial
A36: 035 | B36: =_xlfn.CONCAT("CL-",A36) -> CL-035 | C36: =_xlfn.XLOOKUP($F36,'03_Component'!$C:$C,'03_Component'!$B:$B) -> COMP-034 | D36: =_xlfn.XLOOKUP($G36,'02_Location'!$B:$B,'02_Location'!$A:$A) -> LOC-009 | F36: Cat Bed | G36: Residential
A37: 036 | B37: =_xlfn.CONCAT("CL-",A37) -> CL-036 | C37: =_xlfn.XLOOKUP($F37,'03_Component'!$C:$C,'03_Component'!$B:$B) -> COMP-034 | D37: =_xlfn.XLOOKUP($G37,'02_Location'!$B:$B,'02_Location'!$A:$A) -> LOC-002 | F37: Cat Bed | G37: Commercial
A38: 037 | B38: =_xlfn.CONCAT("CL-",A38) -> CL-037 | C38: =_xlfn.XLOOKUP($F38,'03_Component'!$C:$C,'03_Component'!$B:$B) -> COMP-035 | D38: =_xlfn.XLOOKUP($G38,'02_Location'!$B:$B,'02_Location'!$A:$A) -> LOC-007 | F38: Chemicals | G38: Medical
A39: 038 | B39: =_xlfn.CONCAT("CL-",A39) -> CL-038 | C39: =_xlfn.XLOOKUP($F39,'03_Component'!$C:$C,'03_Component'!$B:$B) -> COMP-035 | D39: =_xlfn.XLOOKUP($G39,'02_Location'!$B:$B,'02_Location'!$A:$A) -> LOC-009 | F39: Chemicals | G39: Residential
A40: 039 | B40: =_xlfn.CONCAT("CL-",A40) -> CL-039 | C40: =_xlfn.XLOOKUP($F40,'03_Component'!$C:$C,'03_Component'!$B:$B) -> COMP-035 | D40: =_xlfn.XLOOKUP($G40,'02_Location'!$B:$B,'02_Location'!$A:$A) -> LOC-006 | F40: Chemicals | G40: Mechanical
...

Sheet 06_DismantleResults
A1: numeric | B1: DismantleID | C1: SourceComponentID | D1: ResultComponentID | E1: Quantity | G1: SrcComp (Plaintext) | H1: ResComp(Plaintext)
A2: 001 | B2: =_xlfn.CONCAT("DIS-",A2) -> DIS-001 | C2: =_xlfn.XLOOKUP($G2,'03_Component'!$C:$C,'03_Component'!$B:$B) -> COMP-002 | D2: =_xlfn.XLOOKUP($H2,'03_Component'!$C:$C,'03_Component'!$B:$B) -> COMP-059 | E2: 1 | G2: Advanced Electrical Components | H2: Electrical Components
A3: 002 | B3: =_xlfn.CONCAT("DIS-",A3) -> DIS-002 | C3: =_xlfn.XLOOKUP($G3,'03_Component'!$C:$C,'03_Component'!$B:$B) -> COMP-002 | D3: =_xlfn.XLOOKUP($H3,'03_Component'!$C:$C,'03_Component'!$B:$B) -> COMP-175 | E3: 1 | G3: Advanced Electrical Components | H3: Wires
A4: 003 | B4: =_xlfn.CONCAT("DIS-",A4) -> DIS-003 | C4: =_xlfn.XLOOKUP($G4,'03_Component'!$C:$C,'03_Component'!$B:$B) -> COMP-003 | D4: =_xlfn.XLOOKUP($H4,'03_Component'!$C:$C,'03_Component'!$B:$B) -> COMP-093 | E4: 1 | G4: Advanced Mechanical Components | H4: Mechanical Components
A5: 004 | B5: =_xlfn.CONCAT("DIS-",A5) -> DIS-004 | C5: =_xlfn.XLOOKUP($G5,'03_Component'!$C:$C,'03_Component'!$B:$B) -> COMP-003 | D5: =_xlfn.XLOOKUP($H5,'03_Component'!$C:$C,'03_Component'!$B:$B) -> COMP-175 | E5: 1 | G5: Advanced Mechanical Components | H5: Wires
A6: 005 | B6: =_xlfn.CONCAT("DIS-",A6) -> DIS-005 | C6: =_xlfn.XLOOKUP($G6,'03_Component'!$C:$C,'03_Component'!$B:$B) -> COMP-004 | D6: =_xlfn.XLOOKUP($H6,'03_Component'!$C:$C,'03_Component'!$B:$B) -> COMP-018 | E6: 3 | G6: Agave | H6: Assorted Seeds
A7: 006 | B7: =_xlfn.CONCAT("DIS-",A7) -> DIS-006 | C7: =_xlfn.XLOOKUP($G7,'03_Component'!$C:$C,'03_Component'!$B:$B) -> COMP-005 | D7: =_xlfn.XLOOKUP($H7,'03_Component'!$C:$C,'03_Component'!$B:$B) -> 0 | E7: 0 | G7: Air Freshener
A8: 007 | B8: =_xlfn.CONCAT("DIS-",A8) -> DIS-007 | C8: =_xlfn.XLOOKUP($G8,'03_Component'!$C:$C,'03_Component'!$B:$B) -> COMP-006 | D8: =_xlfn.XLOOKUP($H8,'03_Component'!$C:$C,'03_Component'!$B:$B) -> COMP-118 | E8: 1 | G8: Alarm Clock | H8: Processor
A9: 008 | B9: =_xlfn.CONCAT("DIS-",A9) -> DIS-008 | C9: =_xlfn.XLOOKUP($G9,'03_Component'!$C:$C,'03_Component'!$B:$B) -> COMP-006 | D9: =_xlfn.XLOOKUP($H9,'03_Component'!$C:$C,'03_Component'!$B:$B) -> COMP-107 | E9: 6 | G9: Alarm Clock | H9: Plastic Parts
A10: 009 | B10: =_xlfn.CONCAT("DIS-",A10) -> DIS-009 | C10: =_xlfn.XLOOKUP($G10,'03_Component'!$C:$C,'03_Component'!$B:$B) -> COMP-007 | D10: =_xlfn.XLOOKUP($H10,'03_Component'!$C:$C,'03_Component'!$B:$B) -> COMP-035 | E10: 10 | G10: Antiseptic | H10: Chemicals
A11: 010 | B11: =_xlfn.CONCAT("DIS-",A11) -> DIS-010 | C11: =_xlfn.XLOOKUP($G11,'03_Component'!$C:$C,'03_Component'!$B:$B) -> COMP-008 | D11: =_xlfn.XLOOKUP($H11,'03_Component'!$C:$C,'03_Component'!$B:$B) -> COMP-018 | E11: 3 | G11: Apricot | H11: Assorted Seeds
A12: 011 | B12: =_xlfn.CONCAT("DIS-",A12) -> DIS-011 | C12: =_xlfn.XLOOKUP($G12,'03_Component'!$C:$C,'03_Component'!$B:$B) -> COMP-009 | D12: =_xlfn.XLOOKUP($H12,'03_Component'!$C:$C,'03_Component'!$B:$B) -> COMP-096 | E12: 2 | G12: ARC Alloy | H12: Metal Parts
A13: 012 | B13: =_xlfn.CONCAT("DIS-",A13) -> DIS-012 | C13: =_xlfn.XLOOKUP($G13,'03_Component'!$C:$C,'03_Component'!$B:$B) -> COMP-010 | D13: =_xlfn.XLOOKUP($H13,'03_Component'!$C:$C,'03_Component'!$B:$B) -> COMP-009 | E13: 2 | G13: ARC Circuitry | H13: ARC Alloy
A14: 013 | B14: =_xlfn.CONCAT("DIS-",A14) -> DIS-013 | C14: =_xlfn.XLOOKUP($G14,'03_Component'!$C:$C,'03_Component'!$B:$B) -> COMP-011 | D14: =_xlfn.XLOOKUP($H14,'03_Component'!$C:$C,'03_Component'!$B:$B) -> COMP-035 | E14: 16 | G14: ARC Coolant | H14: Chemicals
A15: 014 | B15: =_xlfn.CONCAT("DIS-",A15) -> DIS-014 | C15: =_xlfn.XLOOKUP($G15,'03_Component'!$C:$C,'03_Component'!$B:$B) -> COMP-012 | D15: =_xlfn.XLOOKUP($H15,'03_Component'!$C:$C,'03_Component'!$B:$B) -> COMP-133 | E15: 16 | G15: ARC Flex Rubber | H15: Rubber Parts
A16: 015 | B16: =_xlfn.CONCAT("DIS-",A16) -> DIS-015 | C16: =_xlfn.XLOOKUP($G16,'03_Component'!$C:$C,'03_Component'!$B:$B) -> COMP-013 | D16: =_xlfn.XLOOKUP($H16,'03_Component'!$C:$C,'03_Component'!$B:$B) -> COMP-009 | E16: 2 | G16: ARC Motion Core | H16: ARC Alloy
A17: 016 | B17: =_xlfn.CONCAT("DIS-",A17) -> DIS-016 | C17: =_xlfn.XLOOKUP($G17,'03_Component'!$C:$C,'03_Component'!$B:$B) -> COMP-014 | D17: =_xlfn.XLOOKUP($H17,'03_Component'!$C:$C,'03_Component'!$B:$B) -> COMP-096 | E17: 12 | G17: ARC Performance Steel | H17: Metal Parts
A18: 017 | B18: =_xlfn.CONCAT("DIS-",A18) -> DIS-017 | C18: =_xlfn.XLOOKUP($G18,'03_Component'!$C:$C,'03_Component'!$B:$B) -> COMP-015 | D18: =_xlfn.XLOOKUP($H18,'03_Component'!$C:$C,'03_Component'!$B:$B) -> 0 | E18: 0 | G18: ARC Powercell
A19: 018 | B19: =_xlfn.CONCAT("DIS-",A19) -> DIS-018 | C19: =_xlfn.XLOOKUP($G19,'03_Component'!$C:$C,'03_Component'!$B:$B) -> COMP-016 | D19: =_xlfn.XLOOKUP($H19,'03_Component'!$C:$C,'03_Component'!$B:$B) -> COMP-107 | E19: 14 | G19: ARC Synthetic Resin | H19: Plastic Parts
A20: 019 | B20: =_xlfn.CONCAT("DIS-",A20) -> DIS-019 | C20: =_xlfn.XLOOKUP($G20,'03_Component'!$C:$C,'03_Component'!$B:$B) -> COMP-017 | D20: =_xlfn.XLOOKUP($H20,'03_Component'!$C:$C,'03_Component'!$B:$B) -> COMP-065 | E20: 16 | G20: ARC Thermo Lining | H20: Fabric
A21: 020 | B21: =_xlfn.CONCAT("DIS-",A21) -> DIS-020 | C21: =_xlfn.XLOOKUP($G21,'03_Component'!$C:$C,'03_Component'!$B:$B) -> COMP-018 | D21: =_xlfn.XLOOKUP($H21,'03_Component'!$C:$C,'03_Component'!$B:$B) -> 0 | E21: 0 | G21: Assorted Seeds
A22: 021 | B22: =_xlfn.CONCAT("DIS-",A22) -> DIS-021 | C22: =_xlfn.XLOOKUP($G22,'03_Component'!$C:$C,'03_Component'!$B:$B) -> COMP-019 | D22: =_xlfn.XLOOKUP($H22,'03_Component'!$C:$C,'03_Component'!$B:$B) -> COMP-013 | E22: 2 | G22: Bastion Cell | H22: ARC Motion Core
A23: 022 | B23: =_xlfn.CONCAT("DIS-",A23) -> DIS-022 | C23: =_xlfn.XLOOKUP($G23,'03_Component'!$C:$C,'03_Component'!$B:$B) -> COMP-019 | D23: =_xlfn.XLOOKUP($H23,'03_Component'!$C:$C,'03_Component'!$B:$B) -> COMP-003 | E23: 2 | G23: Bastion Cell | H23: Advanced Mechanical Components
A24: 023 | B24: =_xlfn.CONCAT("DIS-",A24) -> DIS-023 | C24: =_xlfn.XLOOKUP($G24,'03_Component'!$C:$C,'03_Component'!$B:$B) -> COMP-020 | D24: =_xlfn.XLOOKUP($H24,'03_Component'!$C:$C,'03_Component'!$B:$B) -> COMP-096 | E24: 2 | G24: Battery | H24: Metal Parts
A25: 024 | B25: =_xlfn.CONCAT("DIS-",A25) -> DIS-024 | C25: =_xlfn.XLOOKUP($G25,'03_Component'!$C:$C,'03_Component'!$B:$B) -> COMP-021 | D25: =_xlfn.XLOOKUP($H25,'03_Component'!$C:$C,'03_Component'!$B:$B) -> COMP-033 | E25: 4 | G25: Bicycle Pump | H25: Canister
A26: 025 | B26: =_xlfn.CONCAT("DIS-",A26) -> DIS-025 | C26: =_xlfn.XLOOKUP($G26,'03_Component'!$C:$C,'03_Component'!$B:$B) -> COMP-021 | D26: =_xlfn.XLOOKUP($H26,'03_Component'!$C:$C,'03_Component'!$B:$B) -> COMP-096 | E26: 10 | G26: Bicycle Pump | H26: Metal Parts
A27: 026 | B27: =_xlfn.CONCAT("DIS-",A27) -> DIS-026 | C27: =_xlfn.XLOOKUP($G27,'03_Component'!$C:$C,'03_Component'!$B:$B) -> COMP-022 | D27: =_xlfn.XLOOKUP($H27,'03_Component'!$C:$C,'03_Component'!$B:$B) -> 0 | E27: 0 | G27: Bloated Tuna Can
A28: 027 | B28: =_xlfn.CONCAT("DIS-",A28) -> DIS-027 | C28: =_xlfn.XLOOKUP($G28,'03_Component'!$C:$C,'03_Component'!$B:$B) -> COMP-023 | D28: =_xlfn.XLOOKUP($H28,'03_Component'!$C:$C,'03_Component'!$B:$B) -> 0 | E28: 0 | G28: Blown Fuses
A29: 028 | B29: =_xlfn.CONCAT("DIS-",A29) -> DIS-028 | C29: =_xlfn.XLOOKUP($G29,'03_Component'!$C:$C,'03_Component'!$B:$B) -> COMP-024 | D29: =_xlfn.XLOOKUP($H29,'03_Component'!$C:$C,'03_Component'!$B:$B) -> COMP-003 | E29: 2 | G29: Bombardier Cell | H29: Advanced Mechanical Components
A30: 029 | B30: =_xlfn.CONCAT("DIS-",A30) -> DIS-029 | C30: =_xlfn.XLOOKUP($G30,'03_Component'!$C:$C,'03_Component'!$B:$B) -> COMP-024 | D30: =_xlfn.XLOOKUP($H30,'03_Component'!$C:$C,'03_Component'!$B:$B) -> COMP-009 | E30: 2 | G30: Bombardier Cell | H30: ARC Alloy
A31: 030 | B31: =_xlfn.CONCAT("DIS-",A31) -> DIS-030 | C31: =_xlfn.XLOOKUP($G31,'03_Component'!$C:$C,'03_Component'!$B:$B) -> COMP-025 | D31: =_xlfn.XLOOKUP($H31,'03_Component'!$C:$C,'03_Component'!$B:$B) -> 0 | E31: 0 | G31: Breathtaking Snow Globe
A32: 031 | B32: =_xlfn.CONCAT("DIS-",A32) -> DIS-031 | C32: =_xlfn.XLOOKUP($G32,'03_Component'!$C:$C,'03_Component'!$B:$B) -> COMP-026 | D32: =_xlfn.XLOOKUP($H32,'03_Component'!$C:$C,'03_Component'!$B:$B) -> COMP-020 | E32: 3 | G32: Broken Flashlight | H32: Battery
A33: 032 | B33: =_xlfn.CONCAT("DIS-",A33) -> DIS-032 | C33: =_xlfn.XLOOKUP($G33,'03_Component'!$C:$C,'03_Component'!$B:$B) -> COMP-026 | D33: =_xlfn.XLOOKUP($H33,'03_Component'!$C:$C,'03_Component'!$B:$B) -> COMP-096 | E33: 7 | G33: Broken Flashlight | H33: Metal Parts
A34: 033 | B34: =_xlfn.CONCAT("DIS-",A34) -> DIS-033 | C34: =_xlfn.XLOOKUP($G34,'03_Component'!$C:$C,'03_Component'!$B:$B) -> COMP-027 | D34: =_xlfn.XLOOKUP($H34,'03_Component'!$C:$C,'03_Component'!$B:$B) -> COMP-146 | E34: 3 | G34: Broken Handheld Radio | H34: Sensors
A35: 034 | B35: =_xlfn.CONCAT("DIS-",A35) -> DIS-034 | C35: =_xlfn.XLOOKUP($G35,'03_Component'!$C:$C,'03_Component'!$B:$B) -> COMP-027 | D35: =_xlfn.XLOOKUP($H35,'03_Component'!$C:$C,'03_Component'!$B:$B) -> COMP-175 | E35: 3 | G35: Broken Handheld Radio | H35: Wires
A36: 035 | B36: =_xlfn.CONCAT("DIS-",A36) -> DIS-035 | C36: =_xlfn.XLOOKUP($G36,'03_Component'!$C:$C,'03_Component'!$B:$B) -> COMP-028 | D36: =_xlfn.XLOOKUP($H36,'03_Component'!$C:$C,'03_Component'!$B:$B) -> COMP-107 | E36: 12 | G36: Broken Riot Shield | H36: Plastic Parts
A37: 036 | B37: =_xlfn.CONCAT("DIS-",A37) -> DIS-036 | C37: =_xlfn.XLOOKUP($G37,'03_Component'!$C:$C,'03_Component'!$B:$B) -> COMP-029 | D37: =_xlfn.XLOOKUP($H37,'03_Component'!$C:$C,'03_Component'!$B:$B) -> COMP-020 | E37: 2 | G37: Broken Taser | H37: Battery
A38: 037 | B38: =_xlfn.CONCAT("DIS-",A38) -> DIS-037 | C38: =_xlfn.XLOOKUP($G38,'03_Component'!$C:$C,'03_Component'!$B:$B) -> COMP-029 | D38: =_xlfn.XLOOKUP($H38,'03_Component'!$C:$C,'03_Component'!$B:$B) -> COMP-175 | E38: 2 | G38: Broken Taser | H38: Wires
A39: 038 | B39: =_xlfn.CONCAT("DIS-",A39) -> DIS-038 | C39: =_xlfn.XLOOKUP($G39,'03_Component'!$C:$C,'03_Component'!$B:$B) -> COMP-030 | D39: =_xlfn.XLOOKUP($H39,'03_Component'!$C:$C,'03_Component'!$B:$B) -> COMP-009 | E39: 2 | G39: Burned ARC Circuitry | H39: ARC Alloy
A40: 039 | B40: =_xlfn.CONCAT("DIS-",A40) -> DIS-039 | C40: =_xlfn.XLOOKUP($G40,'03_Component'!$C:$C,'03_Component'!$B:$B) -> COMP-031 | D40: =_xlfn.XLOOKUP($H40,'03_Component'!$C:$C,'03_Component'!$B:$B) -> COMP-107 | E40: 8 | G40: Camera Lens | H40: Plastic Parts
...

Sheet Dashboard
B2: Search for Component: | C2: Antiseptic
B4: Component Details: | C4: Name | D4: Rarity | E4: Sell Price | F4: Total Qty Needed | G4: Known Uses | H4: Found In | I4: Dismantles Into
C5: {=_xlfn.LET(_xlpm.compID,IFERROR(_xlfn.XLOOKUP(C2,tblComponent[ComponentName],tblComponent[ComponentID]),""),_xlpm.name,IFERROR(_xlfn.XLOOKUP(_xlpm.compID,tblComponent[ComponentID],tblComponent[ComponentName]),"Not Found"),_xlpm.ComponentRarity,IFERROR(_xlfn.XLOOKUP(_xlpm.compID,tblComponent[ComponentID],tblComponent[ComponentRarity]),""),_xlpm.price,IFERROR(_xlfn.XLOOKUP(_xlpm.compID,tblComponent[ComponentID],tblComponent[ComponentSellPrice]),""),_xlpm.totalNeeded,IFERROR(SUMIFS(tblComponentUsage[UsageQuantity],tblComponentUsage[ComponentID],_xlpm.compID),0),_xlpm.uses,IF(_xlpm.compID="","No uses",IFERROR(_xlfn.TEXTJOIN(", ",TRUE,_xlfn._xlws.FILTER(tblCraftable[CraftableName]&" ("&tblComponentUsage[UsageQuantity]&")",tblComponentUsage[ComponentID]=_xlpm.compID)),"No uses")),_xlpm.Location,IF(_xlpm.compID="","Unknown location",_xlfn.LET(_xlpm.locationIDs,_xlfn._xlws.FILTER(tblComponentLocation[LocationID],tblComponentLocation[ComponentID]=_xlpm.compID),_xlpm.locationNames,_xlfn.IFNA(_xlfn.XLOOKUP(_xlpm.locationIDs,tblLocation[LocationID],tblLocation[LocationName]),"#MISSING"),_xlfn.TEXTJOIN(", ",TRUE,_xlpm.locationNames))),_xlpm.dismantles,IF(_xlpm.compID="","No dismantle",IFERROR(_xlfn.TEXTJOIN(", ",TRUE,_xlfn._xlws.FILTER(tblComponent[ComponentName]&" ("&tblDismantleResults[Quantity]&"x)",(tblDismantleResults[SourceComponentID]=_xlpm.compID)*(tblDismantleResults[ResultComponentID]=tblComponent[ComponentID]))),"No dismantle")),_xlfn.HSTACK(_xlpm.name,_xlpm.ComponentRarity,_xlpm.price,_xlpm.totalNeeded,_xlpm.uses,_xlpm.Location,_xlpm.dismantles))} -> Antiseptic | D5: Blue | E5: 1000 | F5: 9 | G5: No uses | H5: Medical | I5: No dismantle
